Workbook

Sheet Accettazione
A2: ACCETTAZIONE
A4: DOSE IN ARIA (FREE IN AIR)
A6: ACQUISIZIONI ASSIALI (1 fetta) con CI
A7: Posizionare la CI a sbalzo centrata all’isocentro.
G8: Dose free in air
A9: kV | B9: mA | C9: collimazione (mm) | D9: tempo rot (s) | E9: FOV | F9: n. fette | G9: CT exposure (mGycm) | H9: Time (ms) | I9: posiz
A10: 120 | B10: 100 | C10: 10 | D10: 1 | E10: head | F10: 1 | I10: aria
A11: 120 | B11: 100 | C11: 10 | D11: 1 | E11: head | F11: 1 | I11: aria
A12: 120 | B12: 100 | C12: 10 | D12: 1 | E12: head | F12: 1 | I12: aria
A13: 80 | B13: 100 | C13: 10 | D13: 1 | E13: head | F13: 1 | I13: aria
A14: 100 | B14: 100 | C14: 10 | D14: 1 | E14: head | F14: 1 | I14: aria
A15: 140 | B15: 100 | C15: 10 | D15: 1 | E15: head | F15: 1 | I15: aria
A17: ACQUISIZIONI SPIRALI con dose probe
A18: Protocollo TC scelto su Ocean: | D18: Revolution EVO
A19: Posizionare la dose probe a sbalzo centrata all’isocentro.
A21: kV | B21: mA | C21: collimazione (mm) | D21: PITCH | E21: tempo rot (s) | F21: FOV | G21: CTDI 100 (mGy) | H21: posiz
A22: 120 | B22: 100 | C22: 20 x 2,5 | D22: 0.969 | E22: 1 | F22: head | H22: aria
A23: 120 | B23: 100 | C23: 20 x 2,5 | D23: 0.969 | E23: 1 | F23: head | H23: aria
A24: 120 | B24: 100 | C24: 20 x 2,5 | D24: 0.969 | E24: 1 | F24: head | H24: aria
A25: 80 | B25: 100 | C25: 20 x 2,5 | D25: 0.969 | E25: 1 | F25: head | H25: aria | R25: QA phantom | S25: run phantom centering
A26: 100 | B26: 100 | C26: 20 x 2,5 | D26: 0.969 | E26: 1 | F26: head | H26: aria
A27: 140 | B27: 100 | C27: 20 x 2,5 | D27: 0.969 | E27: 1 | F27: head | H27: aria
A30: DOSE IN FANTOCCIO – CAMERA A IONIZZAZIONE (HEAD-BODY)
A31: ACQUISIZIONI ASSIALI (1 fetta) con CI
A33: kV | B33: mA | C33: collimazione (mm) | D33: tempo rot (s) | E33: FOV | F33: CT exposure (mGycm) | G33: Time (ms) | H33: posiz | I33: CTDI vol TC
A34: 80 | B34: 100 | C34: 10 | D34: 1 | E34: head | H34: centro
A35: 100
A36: 120
A37: 140
A38: 80 | H38: h 12
A39: 100
A40: 120
A41: 140
A42: 80 | H42: h 3
A43: 100
A44: 120
A45: 140
A46: 80 | H46: h 6
A47: 100
A48: 120
...

Sheet Accettazione - Catphan
A2: CATPHAN 700
A4: PROTOCOLLO DI ACQUISIZIONE CATPHAN
A6: 1) Laser su fetta di centratura (zero)
A7: 2) Verifica centratura
B8: Tipo controllo | C8: Modalità | D8: Protocollo | E8: Fetta | F8: kV | G8: mA | H8: Tempo rot. [s] | I8: Spessore fetta minimo [mm] | J8: Collimazione | K8: FOV [mm]
B9: tutti | C9: assiale | D9: HEAD | E9: Centratura | F9: 120 | G9: 200 | H9: 1 | I9: 0.625 | J9: 20 x 0,625 | K9: 250
A11: 3) Acquisizioni assiali
B12: Tipo controllo | C12: Modalità | D12: Protocollo | E12: Fetta | F12: kV | G12: mA | H12: Tempo rot. [s] | I12: Spessore fetta [mm] | J12: Collimazione | K12: FOV [mm]
B13: tutti | C13: assiale | D13: HEAD | E13: Centratura | F13: 120 | G13: 200 | H13: 1 | I13: 0.625 | J13: 20 x 0,625 | K13: 250
I14: 1.25 | J14: 20 x 0,625
I15: 2.5 | J15: 20 x 0,625
I16: 5 | J16: 20 x 0,625
I17: 10 | J17: 20 x 0,625
A20: 4) Acquisizioni spirali
B21: Tipo controllo | C21: Modalità | D21: Protocollo | E21: kV | F21: mA | G21: Tempo rot. [s] | H21: Pitch | I21: Spessore fetta [mm] | J21: Collimazione | K21: FOV [mm] | L21: Estensione [mm]
B22: tutti | C22: spirale | D22: HEAD | E22: 120 | F22: 200 | G22: 1 | H22: 1 | I22: 2.5 | J22: 32 x 0,625 | K22: 250 | L22: [-10; +180]
F23: 300
B24: accettazione | E24: 80 | F24: 200
E25: 100
E26: 140
E27: 120 | I27: minimo (es. 0,625) | J27: ??? x minimo
A29: ANALISI DELLE IMMAGINI
A30: Utilizzare sempre le acquisizioni SPIRALI eccetto per l’analisi dello spessore di fetta
A32: Rumore | H32: Da fare anche a un diverso spessore di fetta?
A33: Utilizzare due fette uniformi consecutive + ROI centrale circolare diametro 2 cm
A35: mA | B35: 200
A36: Fetta unif. | B36: # | C36: Area | D36: Media [HU] | E36: Dev std [HU] | F36: Min [HU] | G36: Max [HU]
A37: 1
A38: 2
A40: mA | B40: 300
A41: Fetta unif. | B41: # | C41: Area | D41: Media [HU] | E41: Dev std [HU] | F41: Min [HU] | G41: Max [HU]
A42: 1
A43: 2
A46: Numero CT medio e uniformità numero TC
A47: Utilizzare una fetta uniforme + 5 ROI circolari diametro 2 cm (una centrale e quattro a 1 cm dal bordo della zona omogenea)
A49: mA | B49: 200
A50: ROI | B50: # | C50: Area | D50: Media [HU] | E50: Dev std [HU] | F50: Min [HU] | G50: Max [HU]
A51: centrale
A52: h. 3
A53: h. 6
...

Sheet Report Accettazione
A1: CONTROLLO DI QUALITA' SU SISTEMI DI TOMOGRAFIA COMPUTERIZZATA
A3: Controllo del | C3: 44579
A5: Tipologia di controllo | C5: Prova di accettazione
A6: Azienda | C6: A.O. Ordine Mauriziano
A7: Sala / Unità operativa | C7: DEA – PS
A8: Apparecchiatura | C8: TC
A9: Marca / Modello | C9: GE Revolution EVO
A10: S/N tubo | C10: 5401074 S/N 120265BA4 (feb2024)
A11: Operatori | C11: Isoardi, Cutaia, Farina, Barboni
A13: DOSE IN ARIA
A15: ACQUISIZIONI ASSIALI (1 fetta) – Camera a ionizzazione Pencil 10cm
A17: Riproducibilità del CTDI
A18: kV | B18: mA | C18: collimazione [mm] | D18: tempo rot (s) | E18: FOV
A19: =Accettazione!A10 -> 120 | B19: =Accettazione!B10 -> 100 | C19: =Accettazione!C10 -> 10 | D19: =Accettazione!D10 -> 1 | E19: =Accettazione!E10 -> head
A21: # misura | B21: Dose free air [mGy*cm] | C21: % media | D21: Risultato
A22: 1 | B22: =Accettazione!G10 -> 0 | C22: =(B22-AVERAGE($B$22:$B$24))/AVERAGE($B$22:$B$24) -> #DIV/0! | D22: =IF(ABS(C22)<5%,"ok","no") -> #DIV/0!
A23: 2 | B23: =Accettazione!G11 -> 0 | C23: =(B23-AVERAGE($B$22:$B$24))/AVERAGE($B$22:$B$24) -> #DIV/0! | D23: =IF(ABS(C23)<5%,"ok","no") -> #DIV/0!
A24: 3 | B24: =Accettazione!G12 -> 0 | C24: =(B24-AVERAGE($B$22:$B$24))/AVERAGE($B$22:$B$24) -> #DIV/0! | D24: =IF(ABS(C24)<5%,"ok","no") -> #DIV/0!
A26: Variazione del CTDI in funzione della tensione
A27: mA | B27: collimazione [mm] | C27: tempo rot (s) | D27: FOV
A28: =Accettazione!B13 -> 100 | B28: =Accettazione!C13 -> 10 | C28: =Accettazione!D13 -> 1 | D28: =Accettazione!E13 -> head
A30: kV | B30: Dose free air [mGy*cm] | C30: CTDI100 free in air [mGy]
A31: =Accettazione!A13 -> 80 | B31: =Accettazione!G13 -> 0 | C31: =B31/($B$28/10) -> 0
A32: =Accettazione!A14 -> 100 | B32: =Accettazione!G14 -> 0 | C32: =B32/($B$28/10) -> 0
A33: =Accettazione!A10 -> 120 | B33: =Accettazione!G10 -> 0 | C33: =B33/($B$28/10) -> 0
A34: =Accettazione!A15 -> 140 | B34: =Accettazione!G15 -> 0 | C34: =B34/($B$28/10) -> 0
A36: risultato linearità | B36: 0.9969 | C36: =IF((B36>=0.98),"ok","non superato") -> ok
A38: ACQUISIZIONI SPIRALI – Diodo CT dose profiler
A39: Protocollo Ocean: | B39: =Accettazione!D18 -> Revolution EVO
A40: Riproducibilità del CTDI
A41: kV | B41: mA | C41: collimazione [mm] | D41: pitch | E41: tempo rot (s) | F41: FOV
A42: =Accettazione!A22 -> 120 | B42: =Accettazione!B22 -> 100 | C42: =Accettazione!C22 -> 20 x 2,5 | D42: =Accettazione!D22 -> 0.969 | E42: =Accettazione!E22 -> 1 | F42: =Accettazione!F22 -> head
A44: # misura | B44: Dose free air [mGy*cm] | C44: % media | D44: Risultato
A45: 1 | B45: =Accettazione!G22 -> 0 | C45: =(B45-AVERAGE($B$45:$B$47))/AVERAGE($B$45:$B$47) -> #DIV/0! | D45: =IF(ABS(C45)<5%,"ok","no") -> #DIV/0!
A46: 2 | B46: =Accettazione!G23 -> 0 | C46: =(B46-AVERAGE($B$45:$B$47))/AVERAGE($B$45:$B$47) -> #DIV/0! | D46: =IF(ABS(C46)<5%,"ok","no") -> #DIV/0!
A47: 3 | B47: =Accettazione!G24 -> 0 | C47: =(B47-AVERAGE($B$45:$B$47))/AVERAGE($B$45:$B$47) -> #DIV/0! | D47: =IF(ABS(C47)<5%,"ok","no") -> #DIV/0!
A49: Variazione del CTDI in funzione della tensione
A50: mA | B50: collimazione [mm] | C50: pitch | D50: tempo rot (s) | E50: FOV
A51: =Accettazione!B25 -> 100 | B51: =Accettazione!C25 -> 20 x 2,5 | C51: =Accettazione!D25 -> 0.969 | D51: =Accettazione!E25 -> 1 | E51: =Accettazione!F25 -> head
A53: kV | B53: CTDI [mGy]? Dose free air? [mGy*cm] | C53: Controllare che output dà il diodo
...

Sheet Annuale
A2: ANNUALE
A4: DOSE IN FANTOCCIO – DIODO DOSE PROFILER (HEAD-BODY)
A6: ACQUISIZIONI SPIRALI con dose probe
A7: Protocollo TC scelto su Ocean: | D7: Revolution EVO
A9: kV | B9: mA | C9: collimazione (mm) | D9: pitch | E9: tempo rot (s) | F9: FOV | G9: posiz | H9: CTDI 100 (mGy) | I9: CTDI w (mGy) | J9: CTDI vol (mGy) | K9: CTDIvol TC (mGy) | L9: Δ%
A10: 120 | B10: 100 | C10: 10 | D10: 1 | E10: 0.5 | F10: head | G10: centro | H10: 17.68 | I10: 18.7 | J10: 18.7 | K10: 19.5 | L10: =(K10-J10)/J10 -> 0.042780749
A11: 120 | B11: 100 | C11: 10 | D11: 1 | E11: 0.5 | F11: head | G11: centro | H11: 17.59 | I11: 18.61 | J11: 18.61 | K11: 19.5 | L11: =(K11-J11)/J11 -> 0.047823751
A12: 120 | B12: 100 | C12: 10 | D12: 1 | E12: 0.5 | F12: head | G12: centro | H12: 17.57 | I12: 18.59 | J12: 18.59 | K12: 19.5 | L12: =(K12-J12)/J12 -> 0.048951049
A13: 80 | B13: 100 | C13: 10 | D13: 1 | E13: 0.5 | F13: head | G13: centro | H13: 5.019 | I13: 5.521 | J13: 5.521 | K13: 5.9 | L13: =(K13-J13)/J13 -> 0.068646984
A14: 100 | B14: 100 | C14: 10 | D14: 1 | E14: 0.5 | F14: head | G14: centro | H14: 10.51 | I14: 11.14 | J14: 11.14 | K14: 11.9 | L14: =(K14-J14)/J14 -> 0.068222621
A15: 140 | B15: 100 | C15: 10 | D15: 1 | E15: 0.5 | F15: head | G15: centro | H15: 26 | I15: 27.3 | J15: 27.3 | K15: 28.4 | L15: =(K15-J15)/J15 -> 0.04029304
A16: 120 | B16: 50 | C16: 10 | D16: 1 | E16: 0.5 | F16: head | G16: centro | H16: 8.844 | I16: 9.357 | J16: 9.357 | K16: 9.7 | L16: =(K16-J16)/J16 -> 0.036657048
A17: 120 | B17: 200 | C17: 10 | D17: 1 | E17: 0.5 | F17: head | G17: centro | H17: 35.06 | I17: 37.09 | J17: 37.09 | K17: 39 | L17: =(K17-J17)/J17 -> 0.05149636
A18: 120 | B18: 300 | C18: 10 | D18: 1 | E18: 0.5 | F18: head | G18: centro | H18: 52.48 | I18: 55.53 | J18: 55.53 | K18: 58.4 | L18: =(K18-J18)/J18 -> 0.051683775
A19: 120 | B19: 100 | C19: 40 | D19: 1 | E19: 0.5 | F19: head | G19: centro | H19: 12.88 | I19: 13.62 | J19: 13.62 | K19: 14.3 | L19: =(K19-J19)/J19 -> 0.049926579
A20: 120 | B20: 100 | C20: 10 | D20: 0.42 | E20: 0.5 | F20: head | G20: centro | H20: 7.423 | I20: 7.853 | J20: 18.7 | K20: 19.5 | L20: =(K20-J20)/J20 -> 0.042780749
A21: 120 | B21: 100 | C21: 40 | D21: 0.42 | E21: 0.5 | F21: head | G21: centro | H21: 5.416 | I21: 5.73 | J21: 13.64 | K21: 14.3 | L21: =(K21-J21)/J21 -> 0.048387097
... A23: 120 | B23: 100 | C23: 10 | D23: 1 | E23: 1 | F23: head | G23: centro | H23: 17.6 | I23: 18.62 | J23: 18.62 | K23: 19.5 | L23: =(K23-J23)/J23 -> 0.04726101
A24: 20 | B24: 100 | C24: 10 | D24: 0.969 | E24: 0.5 | F24: large body | G24: centro | L24: =(K24-J24)/J24 -> #DIV/0! | M24: nel software piranha uso fantoccio head | Q24: non inseirta nel report, serve come nostra baseline
A25: 100 | B25: 100 | C25: 10 | D25: 0.969 | E25: 0.5 | F25: large body | G25: centro | L25: =(K25-J25)/J25 -> #DIV/0! | M25: nel software piranha uso fantoccio head
A26: 120 | B26: 100 | C26: 10 | D26: 0.969 | E26: 0.5 | F26: large body | G26: centro | L26: =(K26-J26)/J26 -> #DIV/0! | M26: nel software piranha uso fantoccio head
A27: 140 | B27: 100 | C27: 10 | D27: 0.969 | E27: 0.5 | F27: large body | G27: centro | L27: =(K27-J27)/J27 -> #DIV/0! | M27: nel software piranha uso fantoccio head
A28: No altre collimazioni (2.5, 5, 10… possibili solo in assiale)

Sheet Annuale - Catphan
A2: CATPHAN 700
A4: PROTOCOLLO DI ACQUISIZIONE CATPHAN
A6: 1) Laser su fetta di centratura (zero)
A7: 2) Verifica centratura
B8: Tipo controllo | C8: Modalità | D8: Protocollo | E8: Fetta | F8: kV | G8: mA | H8: Tempo rot. [s] | I8: Spessore fetta minimo [mm] | J8: Collimazione | K8: FOV [mm]
B9: tutti | C9: assiale | D9: HEAD | E9: Centratura | F9: 120 | G9: 200 | H9: 1 | I9: 0.625 | J9: 20 x 0,625 | K9: 250
A11: 3) Acquisizioni assiali
B12: Tipo controllo | C12: Modalità | D12: Protocollo | E12: Fetta | F12: kV | G12: mA | H12: Tempo rot. [s] | I12: Spessore fetta [mm] | J12: Collimazione | K12: FOV [mm]
B13: tutti | C13: assiale | D13: HEAD | E13: Centratura | F13: 120 | G13: 200 | H13: 1 | I13: 0.625 | J13: 20 x 0,625 | K13: 250
I14: 1.25 | J14: 20 x 0,625
I15: 2.5 | J15: 20 x 0,625
I16: 5 | J16: 20 x 0,625
I17: 10 | J17: 20 x 0,625
A20: 4) Acquisizioni spirali
B21: Tipo controllo | C21: Modalità | D21: Protocollo | E21: kV | F21: mA | G21: Tempo rot. [s] | H21: Pitch | I21: Spessore fetta [mm] | J21: Collimazione | K21: FOV [mm] | L21: Estensione [mm]
B22: tutti | C22: spirale | D22: HEAD | E22: 120 | F22: 200 | G22: 1 | H22: 1 | I22: 2.5 | J22: 32 x 0,625 | K22: 250 | L22: [-10; +180]
F23: 300
A25: ANALISI DELLE IMMAGINI
A26: Utilizzare sempre le acquisizioni SPIRALI eccetto per l’analisi dello spessore di fetta
A28: Rumore
A29: Utilizzare due fette uniformi consecutive + ROI centrale circolare diametro 2 cm
A31: mA | B31: 200
A32: Fetta unif. | B32: # | C32: Area | D32: Media [HU] | E32: Dev std [HU] | F32: Min [HU] | G32: Max [HU]
A33: 1
A34: 2
A36: mA | B36: 300
A37: Fetta unif. | B37: # | C37: Area | D37: Media [HU] | E37: Dev std [HU] | F37: Min [HU] | G37: Max [HU]
A38: 1
A39: 2
A42: Numero CT medio e uniformità numero TC
A43: Utilizzare una fetta uniforme + 5 ROI circolari diametro 2 cm (una centrale e quattro a 1 cm dal bordo della zona omogenea)
A45: mA | B45: 200
A46: ROI | B46: # | C46: Area | D46: Media [HU] | E46: Dev std [HU] | F46: Min [HU] | G46: Max [HU]
A47: centrale
A48: h. 3
A49: h. 6
A50: h. 9
A51: h. 12
A54: Accuratezza numero TC
A55: Utilizzare la fetta di centratura + ROI su inserti di densità nota
...

Sheet Report Annuale
A1: CONTROLLO DI QUALITA' SU SISTEMI DI TOMOGRAFIA COMPUTERIZZATA
A3: Controllo del | C3: 46078
A5: Tipologia di controllo | C5: Prova di stato
A6: Azienda | C6: ASL TO 3 Rivoli
A7: Sala / Unità operativa | C7: Radiologia
A8: Apparecchiatura | C8: TC
A9: Marca / Modello | C9: Philips
A10: S/N tubo
A11: Operatori | C11: Bracco, Pinna, Lombardo
A13: DOSE IN FANTOCCIO
A15: ACQUISIZIONI SPIRALI – Diodo CT dose profiler
A16: Protocollo Ocean: | B16: =Annuale!D7 -> Revolution EVO
A18: Fantoccio HEAD
A19: Parametri di baseline | B19: Parametri di baseline | C19: Parametri di baseline | D19: Parametri di baseline | E19: Parametri di baseline | F19: Parametri di baseline
A20: Tensione [kV] | B20: mA | C20: collimazione [mm] | D20: pitch | E20: tempo rot (s) | F20: FOV
A21: =Annuale!A10 -> 120 | B21: =Annuale!B10 -> 100 | C21: =Annuale!C10 -> 10 | D21: =Annuale!D10 -> 1 | E21: =Annuale!E10 -> 0.5 | F21: =Annuale!F10 -> head
A23: Riproducibilità del CTDI
A24: # misura | B24: CTDIvol [mGy] | C24: % media | D24: Risultato
A25: 1 | B25: =Annuale!J10 -> 18.7 | C25: =(B25-AVERAGE($B$25:$B$27))/AVERAGE($B$25:$B$27) -> 0.0035778175 | D25: =IF(ABS(C25)<5%,"ok","no") -> ok
A26: 2 | B26: =Annuale!J11 -> 18.61 | C26: =(B26-AVERAGE($B$25:$B$27))/AVERAGE($B$25:$B$27) -> -0.0012522361 | D26: =IF(ABS(C26)<5%,"ok","no") -> ok
A27: 3 | B27: =Annuale!J12 -> 18.59 | C27: =(B27-AVERAGE($B$25:$B$27))/AVERAGE($B$25:$B$27) -> -0.0023255814 | D27: =IF(ABS(C27)<5%,"ok","no") -> ok
A28: Media | B28: =AVERAGE(B25:B27) -> 18.633333 | C28: Scarto | D28: Risultato
A29: Rif. (accettazione) | B29: =AVERAGE('Report Accettazione'!B110:B112) -> 0 | C29: =(B28-B29)/B29 -> #DIV/0! | D29: =IF(ABS(C29)<20%,"ok","no") -> #DIV/0!
A31: Variazione del CTDI in funzione della tensione
A32: Tensione [kV] | B32: CTDIvol[mGy] | C32: Rif. (accettazione) | D32: Scarto % rif. | E32: Risultato (c.a.<20%) | F32: CTDIvol TC [mGy] | G32: Scarto % TC-misura | H32: Risultato (c.a.<20%)
A33: =Annuale!A13 -> 80 | B33: =Annuale!J13 -> 5.521 | C33: ='Report Accettazione'!B116 -> 0 | D33: =(B33-C33)/C33 -> #DIV/0! | E33: =IF(ABS(D33)<20%,"ok","no") -> #DIV/0! | F33: =Annuale!K13 -> 5.9 | G33: =(F33-B33)/B33 -> 0.068646984 | H33: =IF(ABS(G33)<20%,"ok","no") -> ok
A34: =Annuale!A14 -> 100 | B34: =Annuale!J14 -> 11.14 | C34: ='Report Accettazione'!B117 -> 0 | D34: =(B34-C34)/C34 -> #DIV/0! | E34: =IF(ABS(D34)<20%,"ok","no") -> #DIV/0! | F34: =Annuale!K14 -> 11.9 | G34: =(F34-B34)/B34 -> 0.068222621 | H34: =IF(ABS(G34)<20%,"ok","no") -> ok
A35: =Annuale!A10 -> 120 | B35: =Annuale!J10 -> 18.7 | C35: ='Report Accettazione'!B118 -> 0 | D35: =(B35-C35)/C35 -> #DIV/0! | E35: =IF(ABS(D35)<20%,"ok","no") -> #DIV/0! | F35: =Annuale!K10 -> 19.5 | G35: =(F35-B35)/B35 -> 0.042780749 | H35: =IF(ABS(G35)<20%,"ok","no") -> ok
A36: =Annuale!A15 -> 140 | B36: =Annuale!J15 -> 27.3 | C36: ='Report Accettazione'!B119 -> 0 | D36: =(B36-C36)/C36 -> #DIV/0! | E36: =IF(ABS(D36)<20%,"ok","no") -> #DIV/0! | F36: =Annuale!K15 -> 28.4 | G36: =(F36-B36)/B36 -> 0.04029304 | H36: =IF(ABS(G36)<20%,"ok","no") -> ok
A38: Variazione del CTDI in funzione della corrente
A39: Corrente [mA] | B39: CTDIvol[mGy] | C39: Rif. (accettazione) | D39: Scarto % rif. | E39: Risultato (c.a.<20%) | F39: CTDIvol TC [mGy] | G39: Scarto % TC-misura | H39: Risultato (c.a.<20%)
A40: =Annuale!B16 -> 50 | B40: =Annuale!J16 -> 9.357 | C40: ='Report Accettazione'!B123 -> 0 | D40: =(B40-C40)/C40 -> #DIV/0! | E40: =IF(ABS(D40)<20%,"ok","no") -> #DIV/0! | F40: =Annuale!K16 -> 9.7 | G40: =(F40-B40)/B40 -> 0.036657048 | H40: =IF(ABS(G40)<20%,"ok","no") -> ok
A41: =Annuale!B10 -> 100 | B41: =Annuale!J10 -> 18.7 | C41: ='Report Accettazione'!B124 -> 0 | D41: =(B41-C41)/C41 -> #DIV/0! | E41: =IF(ABS(D41)<20%,"ok","no") -> #DIV/0! | F41: =Annuale!K10 -> 19.5 | G41: =(F41-B41)/B41 -> 0.042780749 | H41: =IF(ABS(G41)<20%,"ok","no") -> ok
A42: =Annuale!B17 -> 200 | B42: =Annuale!J17 -> 37.09 | C42: ='Report Accettazione'!B125 -> 0 | D42: =(B42-C42)/C42 -> #DIV/0! | E42: =IF(ABS(D42)<20%,"ok","no") -> #DIV/0! | F42: =Annuale!K17 -> 39 | G42: =(F42-B42)/B42 -> 0.05149636 | H42: =IF(ABS(G42)<20%,"ok","no") -> ok
A43: =Annuale!B18 -> 300 | B43: =Annuale!J18 -> 55.53 | C43: ='Report Accettazione'!B126 -> 0 | D43: =(B43-C43)/C43 -> #DIV/0! | E43: =IF(ABS(D43)<20%,"ok","no") -> #DIV/0! | F43: =Annuale!K18 -> 58.4 | G43: =(F43-B43)/B43 -> 0.051683775 | H43: =IF(ABS(G43)<20%,"ok","no") -> ok
A45: Variazione del CTDI in funzione di collimazione e pitch
A46: collimazione [mm] | B46: pitch | C46: CTDIvol[mGy] | D46: Rif. (accettazione) | E46: Scarto % rif. | F46: Risultato (c.a.<20%) | G46: CTDIvol TC [mGy] | H46: Scarto % TC-misura | I46: Risultato (c.a.<20%)
A47: =Annuale!C10 -> 10 | B47: =Annuale!D10 -> 1 | C47: =Annuale!J10 -> 18.7 | D47: ='Report Accettazione'!C130 -> 0 | E47: =(C47-D47)/D47 -> #DIV/0! | F47: =IF(ABS(E47)<20%,"ok","no") -> #DIV/0! | G47: =Annuale!K10 -> 19.5 | H47: =(G47-C47)/C47 -> 0.042780749 | I47: =IF(ABS(H47)<20%,"ok","no") -> ok
A48: =Annuale!C19 -> 40 | B48: =Annuale!D19 -> 1 | C48: =Annuale!J19 -> 13.62 | D48: ='Report Accettazione'!C131 -> 0 | E48: =(C48-D48)/D48 -> #DIV/0! | F48: =IF(ABS(E48)<20%,"ok","no") -> #DIV/0! | G48: =Annuale!K19 -> 14.3 | H48: =(G48-C48)/C48 -> 0.049926579 | I48: =IF(ABS(H48)<20%,"ok","no") -> ok
A49: =Annuale!C20 -> 10 | B49: =Annuale!D20 -> 0.42 | C49: =Annuale!J20 -> 18.7 | D49: ='Report Accettazione'!C132 -> 0 | E49: =(C49-D49)/D49 -> #DIV/0! | F49: =IF(ABS(E49)<20%,"ok","no") -> #DIV/0! | G49: =Annuale!K20 -> 19.5 | H49: =(G49-C49)/C49 -> 0.042780749 | I49: =IF(ABS(H49)<20%,"ok","no") -> ok
...

Sheet Semestrale
A2: SEMESTRALE
A4: DOSE IN FANTOCCIO – DOSE IN ARIA (FREE IN AIR)
A6: Eseguire SOLTANTO o le 6 acquisizioni assiali o le 6 acquisizioni spirali
A8: ACQUISIZIONI ASSIALI (1 fetta) con CI
A9: Posizionare la CI a sbalzo centrata all’isocentro.
G10: Dose free in air
A11: kV | B11: mA | C11: collimazione (mm) | D11: tempo rot (s) | E11: FOV | F11: n. fette | G11: CT exposure (mGycm) | H11: Time (ms) | I11: CTDIvol TC (mGy)
A12: 120 | B12: 100 | C12: 10 | D12: 1 | E12: head | F12: 1
A13: 120 | B13: 100 | C13: 10 | D13: 1 | E13: head | F13: 1
A14: 120 | B14: 100 | C14: 10 | D14: 1 | E14: head | F14: 1
A15: 80 | B15: 100 | C15: 10 | D15: 1 | E15: head | F15: 1
A16: 100 | B16: 100 | C16: 10 | D16: 1 | E16: head | F16: 1
A17: 140 | B17: 100 | C17: 10 | D17: 1 | E17: head | F17: 1
A19: ACQUISIZIONI SPIRALI con dose probe
A20: Protocollo TC scelto su Ocean: | D20: Revolution EVO
A21: Posizionare la dose probe a sbalzo centrata all’isocentro.
A23: kV | B23: mA | C23: collimazione (mm) | D23: pitch | E23: tempo rot (s) | F23: FOV | G23: CTDI 100 (mGy) | H23: Time (ms) | I23: CTDIvol TC (mGy) | N23: BODY | O23: CTDI 100 | P23: CTDI TC
A24: 120 | B24: 100 | C24: 20 x 2,5 | D24: 0.969 | E24: 1 | F24: head | N24: 120 | O24: 23.16 | P24: 9.62
A25: 120 | B25: 100 | C25: 20 x 2,5 | D25: 0.969 | E25: 1 | F25: head | N25: 80 | O25: 8.673 | P25: 3.04
A26: 120 | B26: 100 | C26: 20 x 2,5 | D26: 0.969 | E26: 1 | F26: head | N26: 100 | O26: 15.3 | P26: 5.96
A27: 80 | B27: 100 | C27: 20 x 2,5 | D27: 0.969 | E27: 1 | F27: head | N27: 140 | O27: 31.67 | P27: 13.99
A28: 100 | B28: 100 | C28: 20 x 2,5 | D28: 0.969 | E28: 1 | F28: head
A29: 140 | B29: 100 | C29: 20 x 2,5 | D29: 0.969 | E29: 1 | F29: head

Sheet Semestrale - Catphan
A2: CATPHAN 700
A4: PROTOCOLLO DI ACQUISIZIONE CATPHAN
A6: 1) Laser su fetta di centratura (zero)
A7: 2) Verifica centratura
B8: Tipo controllo | C8: Modalità | D8: Protocollo | E8: Fetta | F8: kV | G8: mA | H8: Tempo rot. [s] | I8: Spessore fetta minimo [mm] | J8: Collimazione | K8: FOV [mm]
B9: tutti | C9: assiale | D9: HEAD | E9: Centratura | F9: 120 | G9: 200 | H9: 1 | I9: 0.625 | J9: 20 x 0,625 | K9: 250
A11: 3) Acquisizioni spirali
B12: Tipo controllo | C12: Modalità | D12: Protocollo | E12: kV | F12: mA | G12: Tempo rot. [s] | H12: Pitch | I12: Spessore fetta [mm] | J12: Collimazione | K12: FOV [mm] | L12: Estensione [mm]
B13: tutti | C13: spirale | D13: HEAD | E13: 120 | F13: 200 | G13: 1 | H13: 0.969 | I13: 2.5 | J13: 32 x 0,625 | K13: head | L13: [I10; S180]
A15: ANALISI DELLE IMMAGINI
A16: Utilizzare sempre le acquisizioni SPIRALI eccetto per l’analisi dello spessore di fetta
A18: Rumore
A19: Utilizzare due fette uniformi consecutive + ROI centrale circolare diametro 2 cm
A21: mA | B21: 200
A22: Fetta unif. | B22: # | C22: Area | D22: Media [HU] | E22: Dev std [HU] | F22: Min [HU] | G22: Max [HU]
A23: 1 | B23: 1
A24: 2 | B24: 2
A26: Numero CT medio e uniformità numero TC
A27: Utilizzare una fetta uniforme + 5 ROI circolari diametro 2 cm (una centrale e quattro a 1 cm dal bordo della zona omogenea)
A29: mA | B29: 200
A30: ROI | B30: # | C30: Area | D30: Media [HU] | E30: Dev std [HU] | F30: Min [HU] | G30: Max [HU]
A31: centrale | B31: 2
A32: h. 3 | B32: 3
A33: h. 6 | B33: 4
A34: h. 9 | B34: 5
A35: h. 12 | B35: 6
A38: Accuratezza numero TC
A39: Utilizzare la fetta di centratura + ROI su inserti di densità nota
B41: mA | C41: 200
B42: kV | C42: 120
A43: kV | B43: Materiale | C43: Media [HU]
A44: 120 | B44: Air
B45: Acrylic
B46: Bone50
B47: LDPE
B48: Bone20
B49: Teflon®
B50: Polystyrene
B51: Delrin®
B52: Lung
...

Sheet Report Semestrale
A1: CONTROLLO DI QUALITA' SU SISTEMI DI TOMOGRAFIA COMPUTERIZZATA
A3: Controllo del | C3: 45950
A5: Tipologia di controllo | C5: Prova di costanza semestrale
A6: Azienda | C6: A.O. Ordine Mauriziano
A7: Sala / Unità operativa | C7: DEA
A8: Apparecchiatura | C8: TC
A9: Marca / Modello | C9: GE Revolution EVO
A10: S/N tubo | C10: 120265BA4
A11: Operatori | C11: Cutaia, De Cilladi, Pinna
A13: DOSE IN ARIA + CONFRONTO DOSE IN FANTOCCIO
A15: ACQUISIZIONI ASSIALI (1 fetta) – Camera a ionizzazione Pencil 10cm
A17: Riproducibilità del CTDI
A18: kV | B18: mA | C18: collimazione [mm] | D18: tempo rot (s) | E18: FOV
A19: =Semestrale!A12 -> 120 | B19: =Semestrale!B12 -> 100 | C19: =Semestrale!C12 -> 10 | D19: =Semestrale!D12 -> 1 | E19: =Semestrale!E12 -> head
A21: # misura | B21: Dose free air [mGy*cm] | C21: % media | D21: Risultato
A22: 1 | B22: =Semestrale!G12 -> 0 | C22: =(B22-AVERAGE($B$22:$B$24))/AVERAGE($B$22:$B$24) -> #DIV/0! | D22: =IF(ABS(C22)<5%,"ok","no") -> #DIV/0!
A23: 2 | B23: =Semestrale!G13 -> 0 | C23: =(B23-AVERAGE($B$22:$B$24))/AVERAGE($B$22:$B$24) -> #DIV/0! | D23: =IF(ABS(C23)<5%,"ok","no") -> #DIV/0!
A24: 3 | B24: =Semestrale!G14 -> 0 | C24: =(B24-AVERAGE($B$22:$B$24))/AVERAGE($B$22:$B$24) -> #DIV/0! | D24: =IF(ABS(C24)<5%,"ok","no") -> #DIV/0!
A26: Variazione del CTDI in funzione della tensione
A27: Confronto con dose in fantoccio HEAD mediante fattori pH
A28: mA | B28: collimazione [mm] | C28: tempo rot (s) | D28: FOV
A29: =Semestrale!B12 -> 100 | B29: =Semestrale!C12 -> 10 | C29: =Semestrale!D12 -> 1 | D29: =Semestrale!E12 -> head
A31: kV | B31: CTDI100 free in air [mGy] | C31: pH C.I. | D31: CTDIvol HEAD (ricavato da pH) [mGy] | E31: CTDIvol HEAD CT [mGy] | F31: Scarto % rif. | G31: Risultato (c.a.<20%)
A32: =Semestrale!A15 -> 80 | B32: =Semestrale!G15/($B$29/10) -> 0 | C32: ='Report Accettazione'!F191 -> #DIV/0! | D32: =B32*C32 -> #DIV/0! | E32: =Semestrale!I15 -> 0 | F32: =(E32-D32)/D32 -> #DIV/0! | G32: =IF(ABS(F32)<20%,"ok","no") -> #DIV/0!
A33: =Semestrale!A16 -> 100 | B33: =Semestrale!G16/($B$29/10) -> 0 | C33: ='Report Accettazione'!F192 -> #DIV/0! | D33: =B33*C33 -> #DIV/0! | E33: =Semestrale!I16 -> 0 | F33: =(E33-D33)/D33 -> #DIV/0! | G33: =IF(ABS(F33)<20%,"ok","no") -> #DIV/0!
A34: =Semestrale!A12 -> 120 | B34: =Semestrale!G12/($B$29/10) -> 0 | C34: ='Report Accettazione'!F193 -> #DIV/0! | D34: =B34*C34 -> #DIV/0! | E34: =Semestrale!I12 -> 0 | F34: =(E34-D34)/D34 -> #DIV/0! | G34: =IF(ABS(F34)<20%,"ok","no") -> #DIV/0!
A35: =Semestrale!A17 -> 140 | B35: =Semestrale!G17/($B$29/10) -> 0 | C35: ='Report Accettazione'!F194 -> #DIV/0! | D35: =B35*C35 -> #DIV/0! | E35: =Semestrale!I17 -> 0 | F35: =(E35-D35)/D35 -> #DIV/0! | G35: =IF(ABS(F35)<20%,"ok","no") -> #DIV/0!
A37: risultato linearità | B37: 0.9969 | C37: =IF((B37>=0.98),"ok","non superato") -> ok
A39: ACQUISIZIONI SPIRALI – Diodo CT dose profiler
A40: Protocollo Ocean: | B40: =Semestrale!D20 -> Revolution EVO
A41: Riproducibilità del CTDI
A42: kV | B42: mA | C42: collimazione [mm] | D42: pitch | E42: tempo rot (s) | F42: FOV
A43: =Semestrale!A24 -> 120 | B43: =Semestrale!B24 -> 100 | C43: =Semestrale!C24 -> 20 x 2,5 | D43: =Semestrale!D24 -> 0.969 | E43: =Semestrale!E24 -> 1 | F43: =Semestrale!F24 -> head
A45: # misura | B45: Dose free air [mGy*cm] | C45: % media | D45: Risultato
A46: 1 | B46: =Semestrale!G24 -> 0 | C46: =(B46-AVERAGE($B$46:$B$48))/AVERAGE($B$46:$B$48) -> #DIV/0! | D46: =IF(ABS(C46)<5%,"ok","no") -> #DIV/0!
A47: 2 | B47: =Semestrale!G25 -> 0 | C47: =(B47-AVERAGE($B$46:$B$48))/AVERAGE($B$46:$B$48) -> #DIV/0! | D47: =IF(ABS(C47)<5%,"ok","no") -> #DIV/0!
A48: 3 | B48: =Semestrale!G26 -> 0 | C48: =(B48-AVERAGE($B$46:$B$48))/AVERAGE($B$46:$B$48) -> #DIV/0! | D48: =IF(ABS(C48)<5%,"ok","no") -> #DIV/0!
A50: Variazione del CTDI in funzione della tensione
A51: Confronto con dose in fantoccio HEAD mediante fattori pH
A52: mA | B52: collimazione [mm] | C52: pitch | D52: tempo rot (s) | E52: FOV
...
